Workbook

Sheet 입력값
A1: ☀️ 태양광 발전 수익분석
A2: ※ 노란색 셀만 수정하세요. 나머지는 자동 계산됩니다.
A4: [설비 및 투자 정보]
A5: 설비용량 | B5: 100 | C5: kW
A6: 총 설치비 | B6: 230000000 | C6: 원
A7: kW당 설치비 | B7: =B6/B5 -> 2300000 | C7: 원/kW
A8: 자기자본 | B8: 90000000 | C8: 원
A9: 대출금 | B9: =B6-B8 -> 140000000 | C9: 원
A10: 대출금리 | B10: 0.047 | C10: (연이율)
A11: 대출기간 | B11: 20 | C11: 년
A12: 거치기간 | B12: 3 | C12: 년
A13: 분석기간 | B13: 20 | C13: 년
A14: 할인율(NPV용) | B14: 0.05 | C14: (연이율)
A16: [발전 및 판매 정보]
A17: 평균 이용률 | B17: 0.15 | C17: (15%=하루평균3.6시간)
A18: 연간 예상 발전량 | B18: =B5*B17*24*365 -> 131400 | C18: kWh/년
A19: 전력판매단가(SMP) | B19: 123 | C19: 원/kWh
A20: REC 단가 | B20: 70 | C20: 원/kWh
A21: 평균 판매단가 | B21: =B19+B20 -> 193 | C21: 원/kWh
A22: 성능저하율 | B22: 0.005 | C22: (연간)
A23: 인버터 교체연도 | B23: 10 | C23: 년차
A25: [비용 정보]
A26: 연 유지보수비 | B26: 1500000 | C26: 원/년
A27: 연 보험/기타비 | B27: 500000 | C27: 원/년
A28: 인버터 교체비용 | B28: 7000000 | C28: 원
A29: 총 연간 운영비 | B29: =B26+B27 -> 2000000 | C29: 원/년
A32: [월별 발전 계수]
A33: 월 | B33: 계수 | C33: 설명
A34: 1 | B34: 0.07 | C34: 겨울(일조량 적음)
A35: 2 | B35: 0.075
A36: 3 | B36: 0.085 | C36: 봄
A37: 4 | B37: 0.095
A38: 5 | B38: 0.1 | C38: 초여름
A39: 6 | B39: 0.09 | C39: 장마전
A40: 7 | B40: 0.075 | C40: 장마
A41: 8 | B41: 0.085
A42: 9 | B42: 0.09 | C42: 가을
A43: 10 | B43: 0.085
A44: 11 | B44: 0.075 | C44: 늦가을
A45: 12 | B45: 0.07 | C45: 겨울
...

Sheet 월별분석
A1: 📊 월별 발전량 및 수익 분석 (1년차 기준)
A3: 월 | B3: 발전계수 | C3: 발전량(kWh) | D3: 매출(원) | E3: 운영비(원) | F3: 순이익(원)
A4: 1 | B4: =입력값!B34 -> 0.07 | C4: =입력값!$B$18*B4 -> 9198 | D4: =C4*입력값!$B$21 -> 1775214 | E4: =입력값!$B$29/12 -> 166666.67 | F4: =D4-E4 -> 1608547.3
A5: 2 | B5: =입력값!B35 -> 0.075 | C5: =입력값!$B$18*B5 -> 9855 | D5: =C5*입력값!$B$21 -> 1902015 | E5: =입력값!$B$29/12 -> 166666.67 | F5: =D5-E5 -> 1735348.3
A6: 3 | B6: =입력값!B36 -> 0.085 | C6: =입력값!$B$18*B6 -> 11169 | D6: =C6*입력값!$B$21 -> 2155617 | E6: =입력값!$B$29/12 -> 166666.67 | F6: =D6-E6 -> 1988950.3
A7: 4 | B7: =입력값!B37 -> 0.095 | C7: =입력값!$B$18*B7 -> 12483 | D7: =C7*입력값!$B$21 -> 2409219 | E7: =입력값!$B$29/12 -> 166666.67 | F7: =D7-E7 -> 2242552.3
A8: 5 | B8: =입력값!B38 -> 0.1 | C8: =입력값!$B$18*B8 -> 13140 | D8: =C8*입력값!$B$21 -> 2536020 | E8: =입력값!$B$29/12 -> 166666.67 | F8: =D8-E8 -> 2369353.3
A9: 6 | B9: =입력값!B39 -> 0.09 | C9: =입력값!$B$18*B9 -> 11826 | D9: =C9*입력값!$B$21 -> 2282418 | E9: =입력값!$B$29/12 -> 166666.67 | F9: =D9-E9 -> 2115751.3
A10: 7 | B10: =입력값!B40 -> 0.075 | C10: =입력값!$B$18*B10 -> 9855 | D10: =C10*입력값!$B$21 -> 1902015 | E10: =입력값!$B$29/12 -> 166666.67 | F10: =D10-E10 -> 1735348.3
A11: 8 | B11: =입력값!B41 -> 0.085 | C11: =입력값!$B$18*B11 -> 11169 | D11: =C11*입력값!$B$21 -> 2155617 | E11: =입력값!$B$29/12 -> 166666.67 | F11: =D11-E11 -> 1988950.3
A12: 9 | B12: =입력값!B42 -> 0.09 | C12: =입력값!$B$18*B12 -> 11826 | D12: =C12*입력값!$B$21 -> 2282418 | E12: =입력값!$B$29/12 -> 166666.67 | F12: =D12-E12 -> 2115751.3
A13: 10 | B13: =입력값!B43 -> 0.085 | C13: =입력값!$B$18*B13 -> 11169 | D13: =C13*입력값!$B$21 -> 2155617 | E13: =입력값!$B$29/12 -> 166666.67 | F13: =D13-E13 -> 1988950.3
A14: 11 | B14: =입력값!B44 -> 0.075 | C14: =입력값!$B$18*B14 -> 9855 | D14: =C14*입력값!$B$21 -> 1902015 | E14: =입력값!$B$29/12 -> 166666.67 | F14: =D14-E14 -> 1735348.3
A15: 12 | B15: =입력값!B45 -> 0.07 | C15: =입력값!$B$18*B15 -> 9198 | D15: =C15*입력값!$B$21 -> 1775214 | E15: =입력값!$B$29/12 -> 166666.67 | F15: =D15-E15 -> 1608547.3
A16: 합계 | B16: =SUM(B4:B15) -> 0.995 | C16: =SUM(C4:C15) -> 130743 | D16: =SUM(D4:D15) -> 25233399 | E16: =SUM(E4:E15) -> 2000000 | F16: =SUM(F4:F15) -> 23233399
A18: ※ 입력값 시트의 발전계수와 단가를 수정하면 자동으로 재계산됩니다.

Sheet 연간분석
A1: 📈 연간 현금흐름 분석
A3: 연차 | B3: 발전량(kWh) | C3: 매출(원) | D3: 운영비(원) | E3: 교체비(원) | F3: 대출상환(원) | G3: 순현금흐름(원) | H3: 누적현금흐름(원) | I3: 회수여부
A4: 0 | G4: =-입력값!B8 -> -90000000 | H4: =G4 -> -90000000
A5: 1 | B5: =입력값!B18*(1-입력값!B22)^(A5-1) -> 131400 | C5: =B5*입력값!B21 -> 25360200 | D5: =입력값!B29 -> 2000000 | E5: =IF(A5=입력값!B23,입력값!B28,0) -> 0 | F5: =IF(A5<=입력값!$B$12,입력값!$B$9*입력값!$B$10,IF(A5<=입력값!$B$11,-PMT(입력값!$B$10,입력값!$B$11-입력값!$B$12,입력값!$B$9),0)) -> 6580000 | G5: =C5-D5-E5-F5 -> 16780200 | H5: =H4+G5 -> -73219800 | I5: =IF(H5>=0,"회수완료","")
A6: 2 | B6: =입력값!B18*(1-입력값!B22)^(A6-1) -> 130743 | C6: =B6*입력값!B21 -> 25233399 | D6: =입력값!B29 -> 2000000 | E6: =IF(A6=입력값!B23,입력값!B28,0) -> 0 | F6: =IF(A6<=입력값!$B$12,입력값!$B$9*입력값!$B$10,IF(A6<=입력값!$B$11,-PMT(입력값!$B$10,입력값!$B$11-입력값!$B$12,입력값!$B$9),0)) -> 6580000 | G6: =C6-D6-E6-F6 -> 16653399 | H6: =H5+G6 -> -56566401 | I6: =IF(H6>=0,"회수완료","")
A7: 3 | B7: =입력값!B18*(1-입력값!B22)^(A7-1) -> 130089.29 | C7: =B7*입력값!B21 -> 25107232 | D7: =입력값!B29 -> 2000000 | E7: =IF(A7=입력값!B23,입력값!B28,0) -> 0 | F7: =IF(A7<=입력값!$B$12,입력값!$B$9*입력값!$B$10,IF(A7<=입력값!$B$11,-PMT(입력값!$B$10,입력값!$B$11-입력값!$B$12,입력값!$B$9),0)) -> 6580000 | G7: =C7-D7-E7-F7 -> 16527232 | H7: =H6+G7 -> -40039169 | I7: =IF(H7>=0,"회수완료","")
A8: 4 | B8: =입력값!B18*(1-입력값!B22)^(A8-1) -> 129438.84 | C8: =B8*입력값!B21 -> 24981696 | D8: =입력값!B29 -> 2000000 | E8: =IF(A8=입력값!B23,입력값!B28,0) -> 0 | F8: =IF(A8<=입력값!$B$12,입력값!$B$9*입력값!$B$10,IF(A8<=입력값!$B$11,-PMT(입력값!$B$10,입력값!$B$11-입력값!$B$12,입력값!$B$9),0)) -> 12141188 | G8: =C8-D8-E8-F8 -> 10840507 | H8: =H7+G8 -> -29198662 | I8: =IF(H8>=0,"회수완료","")
A9: 5 | B9: =입력값!B18*(1-입력값!B22)^(A9-1) -> 128791.64 | C9: =B9*입력값!B21 -> 24856787 | D9: =입력값!B29 -> 2000000 | E9: =IF(A9=입력값!B23,입력값!B28,0) -> 0 | F9: =IF(A9<=입력값!$B$12,입력값!$B$9*입력값!$B$10,IF(A9<=입력값!$B$11,-PMT(입력값!$B$10,입력값!$B$11-입력값!$B$12,입력값!$B$9),0)) -> 12141188 | G9: =C9-D9-E9-F9 -> 10715599 | H9: =H8+G9 -> -18483063 | I9: =IF(H9>=0,"회수완료","")
A10: 6 | B10: =입력값!B18*(1-입력값!B22)^(A10-1) -> 128147.69 | C10: =B10*입력값!B21 -> 24732503 | D10: =입력값!B29 -> 2000000 | E10: =IF(A10=입력값!B23,입력값!B28,0) -> 0 | F10: =IF(A10<=입력값!$B$12,입력값!$B$9*입력값!$B$10,IF(A10<=입력값!$B$11,-PMT(입력값!$B$10,입력값!$B$11-입력값!$B$12,입력값!$B$9),0)) -> 12141188 | G10: =C10-D10-E10-F10 -> 10591315 | H10: =H9+G10 -> -7891747.7 | I10: =IF(H10>=0,"회수완료","")
A11: 7 | B11: =입력값!B18*(1-입력값!B22)^(A11-1) -> 127506.95 | C11: =B11*입력값!B21 -> 24608841 | D11: =입력값!B29 -> 2000000 | E11: =IF(A11=입력값!B23,입력값!B28,0) -> 0 | F11: =IF(A11<=입력값!$B$12,입력값!$B$9*입력값!$B$10,IF(A11<=입력값!$B$11,-PMT(입력값!$B$10,입력값!$B$11-입력값!$B$12,입력값!$B$9),0)) -> 12141188 | G11: =C11-D11-E11-F11 -> 10467652 | H11: =H10+G11 -> 2575904.8 | I11: =IF(H11>=0,"회수완료","") -> 회수완료
A12: 8 | B12: =입력값!B18*(1-입력값!B22)^(A12-1) -> 126869.41 | C12: =B12*입력값!B21 -> 24485797 | D12: =입력값!B29 -> 2000000 | E12: =IF(A12=입력값!B23,입력값!B28,0) -> 0 | F12: =IF(A12<=입력값!$B$12,입력값!$B$9*입력값!$B$10,IF(A12<=입력값!$B$11,-PMT(입력값!$B$10,입력값!$B$11-입력값!$B$12,입력값!$B$9),0)) -> 12141188 | G12: =C12-D12-E12-F12 -> 10344608 | H12: =H11+G12 -> 12920513 | I12: =IF(H12>=0,"회수완료","") -> 회수완료
A13: 9 | B13: =입력값!B18*(1-입력값!B22)^(A13-1) -> 126235.07 | C13: =B13*입력값!B21 -> 24363368 | D13: =입력값!B29 -> 2000000 | E13: =IF(A13=입력값!B23,입력값!B28,0) -> 0 | F13: =IF(A13<=입력값!$B$12,입력값!$B$9*입력값!$B$10,IF(A13<=입력값!$B$11,-PMT(입력값!$B$10,입력값!$B$11-입력값!$B$12,입력값!$B$9),0)) -> 12141188 | G13: =C13-D13-E13-F13 -> 10222179 | H13: =H12+G13 -> 23142692 | I13: =IF(H13>=0,"회수완료","") -> 회수완료
A14: 10 | B14: =입력값!B18*(1-입력값!B22)^(A14-1) -> 125603.89 | C14: =B14*입력값!B21 -> 24241551 | D14: =입력값!B29 -> 2000000 | E14: =IF(A14=입력값!B23,입력값!B28,0) -> 7000000 | F14: =IF(A14<=입력값!$B$12,입력값!$B$9*입력값!$B$10,IF(A14<=입력값!$B$11,-PMT(입력값!$B$10,입력값!$B$11-입력값!$B$12,입력값!$B$9),0)) -> 12141188 | G14: =C14-D14-E14-F14 -> 3100362.4 | H14: =H13+G14 -> 26243055 | I14: =IF(H14>=0,"회수완료","") -> 회수완료
A15: 11 | B15: =입력값!B18*(1-입력값!B22)^(A15-1) -> 124975.87 | C15: =B15*입력값!B21 -> 24120343 | D15: =입력값!B29 -> 2000000 | E15: =IF(A15=입력값!B23,입력값!B28,0) -> 0 | F15: =IF(A15<=입력값!$B$12,입력값!$B$9*입력값!$B$10,IF(A15<=입력값!$B$11,-PMT(입력값!$B$10,입력값!$B$11-입력값!$B$12,입력값!$B$9),0)) -> 12141188 | G15: =C15-D15-E15-F15 -> 9979154.7 | H15: =H14+G15 -> 36222210 | I15: =IF(H15>=0,"회수완료","") -> 회수완료
A16: 12 | B16: =입력값!B18*(1-입력값!B22)^(A16-1) -> 124350.99 | C16: =B16*입력값!B21 -> 23999741 | D16: =입력값!B29 -> 2000000 | E16: =IF(A16=입력값!B23,입력값!B28,0) -> 0 | F16: =IF(A16<=입력값!$B$12,입력값!$B$9*입력값!$B$10,IF(A16<=입력값!$B$11,-PMT(입력값!$B$10,입력값!$B$11-입력값!$B$12,입력값!$B$9),0)) -> 12141188 | G16: =C16-D16-E16-F16 -> 9858553 | H16: =H15+G16 -> 46080762 | I16: =IF(H16>=0,"회수완료","") -> 회수완료
A17: 13 | B17: =입력값!B18*(1-입력값!B22)^(A17-1) -> 123729.24 | C17: =B17*입력값!B21 -> 23879743 | D17: =입력값!B29 -> 2000000 | E17: =IF(A17=입력값!B23,입력값!B28,0) -> 0 | F17: =IF(A17<=입력값!$B$12,입력값!$B$9*입력값!$B$10,IF(A17<=입력값!$B$11,-PMT(입력값!$B$10,입력값!$B$11-입력값!$B$12,입력값!$B$9),0)) -> 12141188 | G17: =C17-D17-E17-F17 -> 9738554.3 | H17: =H16+G17 -> 55819317 | I17: =IF(H17>=0,"회수완료","") -> 회수완료
A18: 14 | B18: =입력값!B18*(1-입력값!B22)^(A18-1) -> 123110.59 | C18: =B18*입력값!B21 -> 23760344 | D18: =입력값!B29 -> 2000000 | E18: =IF(A18=입력값!B23,입력값!B28,0) -> 0 | F18: =IF(A18<=입력값!$B$12,입력값!$B$9*입력값!$B$10,IF(A18<=입력값!$B$11,-PMT(입력값!$B$10,입력값!$B$11-입력값!$B$12,입력값!$B$9),0)) -> 12141188 | G18: =C18-D18-E18-F18 -> 9619155.6 | H18: =H17+G18 -> 65438472 | I18: =IF(H18>=0,"회수완료","") -> 회수완료
A19: 15 | B19: =입력값!B18*(1-입력값!B22)^(A19-1) -> 122495.04 | C19: =B19*입력값!B21 -> 23641542 | D19: =입력값!B29 -> 2000000 | E19: =IF(A19=입력값!B23,입력값!B28,0) -> 0 | F19: =IF(A19<=입력값!$B$12,입력값!$B$9*입력값!$B$10,IF(A19<=입력값!$B$11,-PMT(입력값!$B$10,입력값!$B$11-입력값!$B$12,입력값!$B$9),0)) -> 12141188 | G19: =C19-D19-E19-F19 -> 9500353.8 | H19: =H18+G19 -> 74938826 | I19: =IF(H19>=0,"회수완료","") -> 회수완료
A20: 16 | B20: =입력값!B18*(1-입력값!B22)^(A20-1) -> 121882.56 | C20: =B20*입력값!B21 -> 23523335 | D20: =입력값!B29 -> 2000000 | E20: =IF(A20=입력값!B23,입력값!B28,0) -> 0 | F20: =IF(A20<=입력값!$B$12,입력값!$B$9*입력값!$B$10,IF(A20<=입력값!$B$11,-PMT(입력값!$B$10,입력값!$B$11-입력값!$B$12,입력값!$B$9),0)) -> 12141188 | G20: =C20-D20-E20-F20 -> 9382146.1 | H20: =H19+G20 -> 84320972 | I20: =IF(H20>=0,"회수완료","") -> 회수완료
A21: 17 | B21: =입력값!B18*(1-입력값!B22)^(A21-1) -> 121273.15 | C21: =B21*입력값!B21 -> 23405718 | D21: =입력값!B29 -> 2000000 | E21: =IF(A21=입력값!B23,입력값!B28,0) -> 0 | F21: =IF(A21<=입력값!$B$12,입력값!$B$9*입력값!$B$10,IF(A21<=입력값!$B$11,-PMT(입력값!$B$10,입력값!$B$11-입력값!$B$12,입력값!$B$9),0)) -> 12141188 | G21: =C21-D21-E21-F21 -> 9264529.5 | H21: =H20+G21 -> 93585502 | I21: =IF(H21>=0,"회수완료","") -> 회수완료
A22: 18 | B22: =입력값!B18*(1-입력값!B22)^(A22-1) -> 120666.78 | C22: =B22*입력값!B21 -> 23288689 | D22: =입력값!B29 -> 2000000 | E22: =IF(A22=입력값!B23,입력값!B28,0) -> 0 | F22: =IF(A22<=입력값!$B$12,입력값!$B$9*입력값!$B$10,IF(A22<=입력값!$B$11,-PMT(입력값!$B$10,입력값!$B$11-입력값!$B$12,입력값!$B$9),0)) -> 12141188 | G22: =C22-D22-E22-F22 -> 9147500.9 | H22: =H21+G22 -> 1.02733e+08 | I22: =IF(H22>=0,"회수완료","") -> 회수완료
A23: 19 | B23: =입력값!B18*(1-입력값!B22)^(A23-1) -> 120063.45 | C23: =B23*입력값!B21 -> 23172246 | D23: =입력값!B29 -> 2000000 | E23: =IF(A23=입력값!B23,입력값!B28,0) -> 0 | F23: =IF(A23<=입력값!$B$12,입력값!$B$9*입력값!$B$10,IF(A23<=입력값!$B$11,-PMT(입력값!$B$10,입력값!$B$11-입력값!$B$12,입력값!$B$9),0)) -> 12141188 | G23: =C23-D23-E23-F23 -> 9031057.4 | H23: =H22+G23 -> 1.1176406e+08 | I23: =IF(H23>=0,"회수완료","") -> 회수완료
A24: 20 | B24: =입력값!B18*(1-입력값!B22)^(A24-1) -> 119463.13 | C24: =B24*입력값!B21 -> 23056385 | D24: =입력값!B29 -> 2000000 | E24: =IF(A24=입력값!B23,입력값!B28,0) -> 0 | F24: =IF(A24<=입력값!$B$12,입력값!$B$9*입력값!$B$10,IF(A24<=입력값!$B$11,-PMT(입력값!$B$10,입력값!$B$11-입력값!$B$12,입력값!$B$9),0)) -> 12141188 | G24: =C24-D24-E24-F24 -> 8915196.2 | H24: =H23+G24 -> 1.2067926e+08 | I24: =IF(H24>=0,"회수완료","") -> 회수완료
A26: ※ 대출상환: 거치기간 중 이자만 납부, 이후 원리금균등상환

Sheet 수익성지표
A1: 💰 수익성 지표 요약 | E1: 연차 | F1: 순현금흐름 | G1: 누적현금흐름
E2: =연간분석!A4 -> 0 | F2: =연간분석!G4 -> -90000000 | G2: =연간분석!H4 -> -90000000
A3: [투자 요약] | E3: =연간분석!A5 -> 1 | F3: =연간분석!G5 -> 16780200 | G3: =연간분석!H5 -> -73219800
A4: 총 투자비 | B4: =입력값!B6 -> 230000000 | C4: 원 | E4: =연간분석!A6 -> 2 | F4: =연간분석!G6 -> 16653399 | G4: =연간분석!H6 -> -56566401
A5: 자기자본 | B5: =입력값!B8 -> 90000000 | C5: 원 | E5: =연간분석!A7 -> 3 | F5: =연간분석!G7 -> 16527232 | G5: =연간분석!H7 -> -40039169
A6: 대출금 | B6: =입력값!B9 -> 140000000 | C6: 원 | E6: =연간분석!A8 -> 4 | F6: =연간분석!G8 -> 10840507 | G6: =연간분석!H8 -> -29198662
A7: 1년차 예상 매출 | B7: =연간분석!C5 -> 25360200 | C7: 원 | E7: =연간분석!A9 -> 5 | F7: =연간분석!G9 -> 10715599 | G7: =연간분석!H9 -> -18483063
A8: 1년차 예상 순현금흐름 | B8: =연간분석!G5 -> 16780200 | C8: 원 | E8: =연간분석!A10 -> 6 | F8: =연간분석!G10 -> 10591315 | G8: =연간분석!H10 -> -7891747.7
A9: 20년 총 순현금흐름 | B9: =SUM(연간분석!G4:G24) -> 1.2067926e+08 | C9: 원 | E9: =연간분석!A11 -> 7 | F9: =연간분석!G11 -> 10467652 | G9: =연간분석!H11 -> 2575904.8
E10: =연간분석!A12 -> 8 | F10: =연간분석!G12 -> 10344608 | G10: =연간분석!H12 -> 12920513
A11: [수익성 지표] | E11: =연간분석!A13 -> 9 | F11: =연간분석!G13 -> 10222179 | G11: =연간분석!H13 -> 23142692
A12: 단순 회수기간 | B12: =입력값!B8/연간분석!G5 -> 5.3634641 | C12: 년 | E12: =연간분석!A14 -> 10 | F12: =연간분석!G14 -> 3100362.4 | G12: =연간분석!H14 -> 26243055
A13: 실제 회수 연차 | B13: =MATCH(TRUE,INDEX(연간분석!H4:H24>=0,0),0)-1 -> 7 | C13: 년차 | E13: =연간분석!A15 -> 11 | F13: =연간분석!G15 -> 9979154.7 | G13: =연간분석!H15 -> 36222210
A14: IRR (내부수익률) | B14: =IRR(연간분석!G4:G24) -> 0.11859448 | E14: =연간분석!A16 -> 12 | F14: =연간분석!G16 -> 9858553 | G14: =연간분석!H16 -> 46080762
A15: NPV (순현재가치) | B15: =NPV(입력값!B14,연간분석!G5:G24)+연간분석!G4 -> 48506450 | C15: 원 | E15: =연간분석!A17 -> 13 | F15: =연간분석!G17 -> 9738554.3 | G15: =연간분석!H17 -> 55819317
A16: 총 수익률 (20년) | B16: =SUM(연간분석!G4:G24)/입력값!B8 -> 1.3408806 | E16: =연간분석!A18 -> 14 | F16: =연간분석!G18 -> 9619155.6 | G16: =연간분석!H18 -> 65438472
E17: =연간분석!A19 -> 15 | F17: =연간분석!G19 -> 9500353.8 | G17: =연간분석!H19 -> 74938826
A18: [분석 차트] | E18: =연간분석!A20 -> 16 | F18: =연간분석!G20 -> 9382146.1 | G18: =연간분석!H20 -> 84320972
E19: =연간분석!A21 -> 17 | F19: =연간분석!G21 -> 9264529.5 | G19: =연간분석!H21 -> 93585502
E20: =연간분석!A22 -> 18 | F20: =연간분석!G22 -> 9147500.9 | G20: =연간분석!H22 -> 1.02733e+08
E21: =연간분석!A23 -> 19 | F21: =연간분석!G23 -> 9031057.4 | G21: =연간분석!H23 -> 1.1176406e+08
E22: =연간분석!A24 -> 20 | F22: =연간분석!G24 -> 8915196.2 | G22: =연간분석!H24 -> 1.2067926e+08
